<?xml version="1.0"?>
<robot name="simple_car" xmlns:xacro="http://www.ros.org/wiki/xacro">

  <!-- Car Body -->
  <link name="base_link">
    <visual>
      <origin xyz="0 0 0.1" rpy="0 0 0"/>
      <geometry>
        <box size="1.0 0.5 0.2"/>
      </geometry>
      <material name="blue">
        <color rgba="0 0 1 1"/>
      </material>
    </visual>
    <collision>
      <origin xyz="0 0 0.1" rpy="0 0 0"/>
      <geometry>
        <box size="1.0 0.5 0.2"/>
      </geometry>
    </collision>
    <inertial>
      <mass value="5.0"/>
      <origin xyz="0 0 0.1" rpy="0 0 0"/>
      <inertia ixx="0.1" ixy="0.0" ixz="0.0"
               iyy="0.1" iyz="0.0"
               izz="0.1"/>
    </inertial>
  </link>

  <!-- Wheels -->
  <!-- Wheel Macro -->
  <xacro:macro name="wheel" params="name x y">
    <link name="${name}">
      <visual>
        <origin xyz="${x} ${y} 0.05" rpy="0 0 0"/>
        <geometry>
          <cylinder length="0.05" radius="0.1"/>
        </geometry>
        <material name="black">
          <color rgba="0 0 0 1"/>
        </material>
      </visual>
      <collision>
        <origin xyz="${x} ${y} 0.05" rpy="0 0 0"/>
        <geometry>
          <cylinder length="0.05" radius="0.1"/>
        </geometry>
      </collision>
      <inertial>
        <mass value="1.0"/>
        <origin xyz="0 0 0.05" rpy="0 0 0"/>
        <inertia ixx="0.01" ixy="0.0" ixz="0.0"
                 iyy="0.01" iyz="0.0"
                 izz="0.01"/>
      </inertial>
    </link>

    <joint name="${name}_joint" type="continuous">
      <parent link="base_link"/>
      <child link="${name}"/>
      <origin xyz="${x} ${y} 0" rpy="0 0 0"/>
      <axis xyz="0 1 0"/>
    </joint>
  </xacro:macro>

  <!-- Four Wheels -->
  <xacro:wheel name="front_left_wheel"  x="0.4" y="0.25"/>
  <xacro:wheel name="front_right_wheel" x="0.4" y="-0.25"/>
  <xacro:wheel name="rear_left_wheel"   x="-0.4" y="0.25"/>
  <xacro:wheel name="rear_right_wheel"  x="-0.4" y="-0.25"/>

</robot>
